[2023-08-13T08:30:53.423+0000] {taskinstance.py:1103} INFO - Dependencies all met for dep_context=non-requeueable deps ti=<TaskInstance: tune_dag.check_gpu manual__2023-08-13T08:30:46.531523+00:00 [queued]>
[2023-08-13T08:30:53.426+0000] {taskinstance.py:1103} INFO - Dependencies all met for dep_context=requeueable deps ti=<TaskInstance: tune_dag.check_gpu manual__2023-08-13T08:30:46.531523+00:00 [queued]>
[2023-08-13T08:30:53.426+0000] {taskinstance.py:1308} INFO - Starting attempt 1 of 2
[2023-08-13T08:30:53.437+0000] {taskinstance.py:1327} INFO - Executing <Task(_PythonDecoratedOperator): check_gpu> on 2023-08-13 08:30:46.531523+00:00
[2023-08-13T08:30:53.442+0000] {standard_task_runner.py:57} INFO - Started process 396 to run task
[2023-08-13T08:30:53.443+0000] {standard_task_runner.py:84} INFO - Running: ['***', 'tasks', 'run', 'tune_dag', 'check_gpu', 'manual__2023-08-13T08:30:46.531523+00:00', '--job-id', '127', '--raw', '--subdir', 'DAGS_FOLDER/scripts/tune_ml.py', '--cfg-path', '/tmp/tmpfpl3mfwc']
[2023-08-13T08:30:53.444+0000] {standard_task_runner.py:85} INFO - Job 127: Subtask check_gpu
[2023-08-13T08:30:53.470+0000] {task_command.py:410} INFO - Running <TaskInstance: tune_dag.check_gpu manual__2023-08-13T08:30:46.531523+00:00 [running]> on host 30ba972171bc
[2023-08-13T08:30:53.504+0000] {taskinstance.py:1545} INFO - Exporting env vars: AIRFLOW_CTX_DAG_EMAIL='thanhdong18891@gmail.com' AIRFLOW_CTX_DAG_OWNER='DongNT17' AIRFLOW_CTX_DAG_ID='tune_dag' AIRFLOW_CTX_TASK_ID='check_gpu' AIRFLOW_CTX_EXECUTION_DATE='2023-08-13T08:30:46.531523+00:00' AIRFLOW_CTX_TRY_NUMBER='1' AIRFLOW_CTX_DAG_RUN_ID='manual__2023-08-13T08:30:46.531523+00:00'
[2023-08-13T08:39:03.075+0000] {taskinstance.py:1824} ERROR - Task failed with exception
Traceback (most recent call last):
  File "/home/airflow/.local/lib/python3.10/site-packages/docker/api/client.py", line 268, in _raise_for_status
    response.raise_for_status()
  File "/home/airflow/.local/lib/python3.10/site-packages/requests/models.py", line 1021, in raise_for_status
    raise HTTPError(http_error_msg, response=self)
requests.exceptions.HTTPError: 500 Server Error: Internal Server Error for url: http+docker://localhost/v1.43/containers/52fc1c32dc77a7b061bc6d135266a3357aba8941099450302a884b737e50004a/start

The above exception was the direct cause of the following exception:

Traceback (most recent call last):
  File "/home/airflow/.local/lib/python3.10/site-packages/airflow/decorators/base.py", line 220, in execute
    return_value = super().execute(context)
  File "/home/airflow/.local/lib/python3.10/site-packages/airflow/operators/python.py", line 181, in execute
    return_value = self.execute_callable()
  File "/home/airflow/.local/lib/python3.10/site-packages/airflow/operators/python.py", line 198, in execute_callable
    return self.python_callable(*self.op_args, **self.op_kwargs)
  File "/opt/airflow/dags/scripts/tune_ml.py", line 71, in start_gpu_container
    response = client.containers.run(
  File "/home/airflow/.local/lib/python3.10/site-packages/docker/models/containers.py", line 865, in run
    container.start()
  File "/home/airflow/.local/lib/python3.10/site-packages/docker/models/containers.py", line 406, in start
    return self.client.api.start(self.id, **kwargs)
  File "/home/airflow/.local/lib/python3.10/site-packages/docker/utils/decorators.py", line 19, in wrapped
    return f(self, resource_id, *args, **kwargs)
  File "/home/airflow/.local/lib/python3.10/site-packages/docker/api/container.py", line 1127, in start
    self._raise_for_status(res)
  File "/home/airflow/.local/lib/python3.10/site-packages/docker/api/client.py", line 270, in _raise_for_status
    raise create_api_error_from_http_exception(e) from e
  File "/home/airflow/.local/lib/python3.10/site-packages/docker/errors.py", line 39, in create_api_error_from_http_exception
    raise cls(e, response=response, explanation=explanation) from e
docker.errors.APIError: 500 Server Error for http+docker://localhost/v1.43/containers/52fc1c32dc77a7b061bc6d135266a3357aba8941099450302a884b737e50004a/start: Internal Server Error ("could not select device driver "" with capabilities: [[gpu]]")
[2023-08-13T08:39:03.080+0000] {taskinstance.py:1345} INFO - Marking task as UP_FOR_RETRY. dag_id=tune_dag, task_id=check_gpu, execution_date=20230813T083046, start_date=20230813T083053, end_date=20230813T083903
[2023-08-13T08:39:03.086+0000] {standard_task_runner.py:104} ERROR - Failed to execute job 127 for task check_gpu (500 Server Error for http+docker://localhost/v1.43/containers/52fc1c32dc77a7b061bc6d135266a3357aba8941099450302a884b737e50004a/start: Internal Server Error ("could not select device driver "" with capabilities: [[gpu]]"); 396)
[2023-08-13T08:39:03.113+0000] {local_task_job_runner.py:225} INFO - Task exited with return code 1
[2023-08-13T08:39:03.124+0000] {taskinstance.py:2651} INFO - 0 downstream tasks scheduled from follow-on schedule check
