[2023-08-12T04:49:47.620+0000] {taskinstance.py:1103} INFO - Dependencies all met for dep_context=non-requeueable deps ti=<TaskInstance: tune_dag.tune_task manual__2023-08-12T04:47:49.800785+00:00 [queued]>
[2023-08-12T04:49:47.624+0000] {taskinstance.py:1103} INFO - Dependencies all met for dep_context=requeueable deps ti=<TaskInstance: tune_dag.tune_task manual__2023-08-12T04:47:49.800785+00:00 [queued]>
[2023-08-12T04:49:47.624+0000] {taskinstance.py:1308} INFO - Starting attempt 2 of 2
[2023-08-12T04:49:47.629+0000] {taskinstance.py:1327} INFO - Executing <Task(BashOperator): tune_task> on 2023-08-12 04:47:49.800785+00:00
[2023-08-12T04:49:47.634+0000] {standard_task_runner.py:57} INFO - Started process 278 to run task
[2023-08-12T04:49:47.636+0000] {standard_task_runner.py:84} INFO - Running: ['***', 'tasks', 'run', 'tune_dag', 'tune_task', 'manual__2023-08-12T04:47:49.800785+00:00', '--job-id', '77', '--raw', '--subdir', 'DAGS_FOLDER/scripts/tune_ml.py', '--cfg-path', '/tmp/tmpedz0npir']
[2023-08-12T04:49:47.637+0000] {standard_task_runner.py:85} INFO - Job 77: Subtask tune_task
[2023-08-12T04:49:47.655+0000] {task_command.py:410} INFO - Running <TaskInstance: tune_dag.tune_task manual__2023-08-12T04:47:49.800785+00:00 [running]> on host 67c44e1a363a
[2023-08-12T04:49:47.686+0000] {taskinstance.py:1545} INFO - Exporting env vars: AIRFLOW_CTX_DAG_EMAIL='thanhdong18891@gmail.com' AIRFLOW_CTX_DAG_OWNER='DongNT17' AIRFLOW_CTX_DAG_ID='tune_dag' AIRFLOW_CTX_TASK_ID='tune_task' AIRFLOW_CTX_EXECUTION_DATE='2023-08-12T04:47:49.800785+00:00' AIRFLOW_CTX_TRY_NUMBER='2' AIRFLOW_CTX_DAG_RUN_ID='manual__2023-08-12T04:47:49.800785+00:00'
[2023-08-12T04:49:47.687+0000] {subprocess.py:63} INFO - Tmp dir root location: 
 /tmp
[2023-08-12T04:49:47.687+0000] {subprocess.py:75} INFO - Running command: ['/bin/bash', '-c', ' bash -i /opt/***/dags/scripts/train.sh ']
[2023-08-12T04:49:47.695+0000] {subprocess.py:86} INFO - Output:
[2023-08-12T04:49:47.697+0000] {subprocess.py:93} INFO - bash: cannot set terminal process group (-1): Inappropriate ioctl for device
[2023-08-12T04:49:47.697+0000] {subprocess.py:93} INFO - bash: no job control in this shell
[2023-08-12T04:49:48.744+0000] {subprocess.py:93} INFO - # conda environments:
[2023-08-12T04:49:48.744+0000] {subprocess.py:93} INFO - #
[2023-08-12T04:49:48.744+0000] {subprocess.py:93} INFO - base                     /home/***/conda
[2023-08-12T04:49:48.744+0000] {subprocess.py:93} INFO - training_env          *  /home/***/conda/envs/training_env
[2023-08-12T04:49:48.745+0000] {subprocess.py:93} INFO - 
[2023-08-12T04:49:49.711+0000] {subprocess.py:93} INFO - Traceback (most recent call last):
[2023-08-12T04:49:49.711+0000] {subprocess.py:93} INFO -   File "/home/***/dog_cat_mlops/./ml/train.py", line 17, in <module>
[2023-08-12T04:49:49.712+0000] {subprocess.py:93} INFO -     model = models.resnet50().cuda()
[2023-08-12T04:49:49.712+0000] {subprocess.py:93} INFO -             ^^^^^^^^^^^^^^^^^^^^^^^^
[2023-08-12T04:49:49.712+0000] {subprocess.py:93} INFO -   File "/home/***/conda/envs/training_env/lib/python3.11/site-packages/torch/nn/modules/module.py", line 905, in cuda
[2023-08-12T04:49:49.712+0000] {subprocess.py:93} INFO -     return self._apply(lambda t: t.cuda(device))
[2023-08-12T04:49:49.712+0000] {subprocess.py:93} INFO -            ^^^^^^^^^^^^^^^^^^^^^^^^^^^^^^^^^^^^^
[2023-08-12T04:49:49.712+0000] {subprocess.py:93} INFO -   File "/home/***/conda/envs/training_env/lib/python3.11/site-packages/torch/nn/modules/module.py", line 797, in _apply
[2023-08-12T04:49:49.712+0000] {subprocess.py:93} INFO -     module._apply(fn)
[2023-08-12T04:49:49.712+0000] {subprocess.py:93} INFO -   File "/home/***/conda/envs/training_env/lib/python3.11/site-packages/torch/nn/modules/module.py", line 820, in _apply
[2023-08-12T04:49:49.712+0000] {subprocess.py:93} INFO -     param_applied = fn(param)
[2023-08-12T04:49:49.712+0000] {subprocess.py:93} INFO -                     ^^^^^^^^^
[2023-08-12T04:49:49.712+0000] {subprocess.py:93} INFO -   File "/home/***/conda/envs/training_env/lib/python3.11/site-packages/torch/nn/modules/module.py", line 905, in <lambda>
[2023-08-12T04:49:49.712+0000] {subprocess.py:93} INFO -     return self._apply(lambda t: t.cuda(device))
[2023-08-12T04:49:49.712+0000] {subprocess.py:93} INFO -                                  ^^^^^^^^^^^^^^
[2023-08-12T04:49:49.712+0000] {subprocess.py:93} INFO -   File "/home/***/conda/envs/training_env/lib/python3.11/site-packages/torch/cuda/__init__.py", line 239, in _lazy_init
[2023-08-12T04:49:49.712+0000] {subprocess.py:93} INFO -     raise AssertionError("Torch not compiled with CUDA enabled")
[2023-08-12T04:49:49.712+0000] {subprocess.py:93} INFO - AssertionError: Torch not compiled with CUDA enabled
[2023-08-12T04:49:49.853+0000] {subprocess.py:97} INFO - Command exited with return code 1
[2023-08-12T04:49:49.858+0000] {taskinstance.py:1824} ERROR - Task failed with exception
Traceback (most recent call last):
  File "/home/airflow/.local/lib/python3.10/site-packages/airflow/operators/bash.py", line 210, in execute
    raise AirflowException(
airflow.exceptions.AirflowException: Bash command failed. The command returned a non-zero exit code 1.
[2023-08-12T04:49:49.859+0000] {taskinstance.py:1345} INFO - Marking task as FAILED. dag_id=tune_dag, task_id=tune_task, execution_date=20230812T044749, start_date=20230812T044947, end_date=20230812T044949
[2023-08-12T04:49:49.875+0000] {warnings.py:109} WARNING - /home/***/.local/lib/python3.10/site-packages/***/utils/email.py:152: RemovedInAirflow3Warning: Fetching SMTP credentials from configuration variables will be deprecated in a future release. Please set credentials using a connection instead.
  send_mime_email(e_from=mail_from, e_to=recipients, mime_msg=msg, conn_id=conn_id, dryrun=dryrun)

[2023-08-12T04:49:49.876+0000] {configuration.py:676} WARNING - section/key [smtp/smtp_user] not found in config
[2023-08-12T04:49:49.876+0000] {email.py:268} INFO - Email alerting: attempt 1
[2023-08-12T04:49:49.879+0000] {configuration.py:676} WARNING - section/key [smtp/smtp_user] not found in config
[2023-08-12T04:49:49.879+0000] {email.py:268} INFO - Email alerting: attempt 1
[2023-08-12T04:49:49.879+0000] {taskinstance.py:1889} ERROR - Failed to send email to: thanhdong18891@gmail.com
Traceback (most recent call last):
  File "/home/airflow/.local/lib/python3.10/site-packages/airflow/models/taskinstance.py", line 1407, in _run_raw_task
    self._execute_task_with_callbacks(context, test_mode)
  File "/home/airflow/.local/lib/python3.10/site-packages/airflow/models/taskinstance.py", line 1558, in _execute_task_with_callbacks
    result = self._execute_task(context, task_orig)
  File "/home/airflow/.local/lib/python3.10/site-packages/airflow/models/taskinstance.py", line 1628, in _execute_task
    result = execute_callable(context=context)
  File "/home/airflow/.local/lib/python3.10/site-packages/airflow/operators/bash.py", line 210, in execute
    raise AirflowException(
airflow.exceptions.AirflowException: Bash command failed. The command returned a non-zero exit code 1.

During handling of the above exception, another exception occurred:

Traceback (most recent call last):
  File "/home/airflow/.local/lib/python3.10/site-packages/airflow/models/taskinstance.py", line 2295, in email_alert
    send_email(task.email, subject, html_content)
  File "/home/airflow/.local/lib/python3.10/site-packages/airflow/utils/email.py", line 78, in send_email
    return backend(
  File "/home/airflow/.local/lib/python3.10/site-packages/airflow/utils/email.py", line 152, in send_email_smtp
    send_mime_email(e_from=mail_from, e_to=recipients, mime_msg=msg, conn_id=conn_id, dryrun=dryrun)
  File "/home/airflow/.local/lib/python3.10/site-packages/airflow/utils/email.py", line 270, in send_mime_email
    smtp_conn = _get_smtp_connection(smtp_host, smtp_port, smtp_timeout, smtp_ssl)
  File "/home/airflow/.local/lib/python3.10/site-packages/airflow/utils/email.py", line 317, in _get_smtp_connection
    else smtplib.SMTP(host=host, port=port, timeout=timeout)
  File "/usr/local/lib/python3.10/smtplib.py", line 255, in __init__
    (code, msg) = self.connect(host, port)
  File "/usr/local/lib/python3.10/smtplib.py", line 341, in connect
    self.sock = self._get_socket(host, port, self.timeout)
  File "/usr/local/lib/python3.10/smtplib.py", line 312, in _get_socket
    return socket.create_connection((host, port), timeout,
  File "/usr/local/lib/python3.10/socket.py", line 845, in create_connection
    raise err
  File "/usr/local/lib/python3.10/socket.py", line 833, in create_connection
    sock.connect(sa)
OSError: [Errno 99] Cannot assign requested address

During handling of the above exception, another exception occurred:

Traceback (most recent call last):
  File "/home/airflow/.local/lib/python3.10/site-packages/airflow/models/taskinstance.py", line 1887, in handle_failure
    self.email_alert(error, task)
  File "/home/airflow/.local/lib/python3.10/site-packages/airflow/models/taskinstance.py", line 2297, in email_alert
    send_email(task.email, subject, html_content_err)
  File "/home/airflow/.local/lib/python3.10/site-packages/airflow/utils/email.py", line 78, in send_email
    return backend(
  File "/home/airflow/.local/lib/python3.10/site-packages/airflow/utils/email.py", line 152, in send_email_smtp
    send_mime_email(e_from=mail_from, e_to=recipients, mime_msg=msg, conn_id=conn_id, dryrun=dryrun)
  File "/home/airflow/.local/lib/python3.10/site-packages/airflow/utils/email.py", line 270, in send_mime_email
    smtp_conn = _get_smtp_connection(smtp_host, smtp_port, smtp_timeout, smtp_ssl)
  File "/home/airflow/.local/lib/python3.10/site-packages/airflow/utils/email.py", line 317, in _get_smtp_connection
    else smtplib.SMTP(host=host, port=port, timeout=timeout)
  File "/usr/local/lib/python3.10/smtplib.py", line 255, in __init__
    (code, msg) = self.connect(host, port)
  File "/usr/local/lib/python3.10/smtplib.py", line 341, in connect
    self.sock = self._get_socket(host, port, self.timeout)
  File "/usr/local/lib/python3.10/smtplib.py", line 312, in _get_socket
    return socket.create_connection((host, port), timeout,
  File "/usr/local/lib/python3.10/socket.py", line 845, in create_connection
    raise err
  File "/usr/local/lib/python3.10/socket.py", line 833, in create_connection
    sock.connect(sa)
OSError: [Errno 99] Cannot assign requested address
[2023-08-12T04:49:49.884+0000] {standard_task_runner.py:104} ERROR - Failed to execute job 77 for task tune_task (Bash command failed. The command returned a non-zero exit code 1.; 278)
[2023-08-12T04:49:49.892+0000] {local_task_job_runner.py:225} INFO - Task exited with return code 1
[2023-08-12T04:49:49.900+0000] {taskinstance.py:2651} INFO - 0 downstream tasks scheduled from follow-on schedule check
