[2023-08-12T15:33:03.571+0000] {taskinstance.py:1103} INFO - Dependencies all met for dep_context=non-requeueable deps ti=<TaskInstance: tune_dag.create_env_task manual__2023-08-12T15:31:09.616182+00:00 [queued]>
[2023-08-12T15:33:03.574+0000] {taskinstance.py:1103} INFO - Dependencies all met for dep_context=requeueable deps ti=<TaskInstance: tune_dag.create_env_task manual__2023-08-12T15:31:09.616182+00:00 [queued]>
[2023-08-12T15:33:03.574+0000] {taskinstance.py:1308} INFO - Starting attempt 2 of 2
[2023-08-12T15:33:03.612+0000] {taskinstance.py:1327} INFO - Executing <Task(BashOperator): create_env_task> on 2023-08-12 15:31:09.616182+00:00
[2023-08-12T15:33:03.617+0000] {standard_task_runner.py:57} INFO - Started process 242 to run task
[2023-08-12T15:33:03.619+0000] {standard_task_runner.py:84} INFO - Running: ['***', 'tasks', 'run', 'tune_dag', 'create_env_task', 'manual__2023-08-12T15:31:09.616182+00:00', '--job-id', '108', '--raw', '--subdir', 'DAGS_FOLDER/scripts/tune_ml.py', '--cfg-path', '/tmp/tmpvbtyoe8w']
[2023-08-12T15:33:03.620+0000] {standard_task_runner.py:85} INFO - Job 108: Subtask create_env_task
[2023-08-12T15:33:03.672+0000] {task_command.py:410} INFO - Running <TaskInstance: tune_dag.create_env_task manual__2023-08-12T15:31:09.616182+00:00 [running]> on host f0a72231051f
[2023-08-12T15:33:03.767+0000] {taskinstance.py:1545} INFO - Exporting env vars: AIRFLOW_CTX_DAG_EMAIL='thanhdong18891@gmail.com' AIRFLOW_CTX_DAG_OWNER='DongNT17' AIRFLOW_CTX_DAG_ID='tune_dag' AIRFLOW_CTX_TASK_ID='create_env_task' AIRFLOW_CTX_EXECUTION_DATE='2023-08-12T15:31:09.616182+00:00' AIRFLOW_CTX_TRY_NUMBER='2' AIRFLOW_CTX_DAG_RUN_ID='manual__2023-08-12T15:31:09.616182+00:00'
[2023-08-12T15:33:03.768+0000] {subprocess.py:63} INFO - Tmp dir root location: 
 /tmp
[2023-08-12T15:33:03.783+0000] {subprocess.py:75} INFO - Running command: ['/bin/bash', '-c', ' bash -i /opt/***/dags/scripts/create_env.sh ']
[2023-08-12T15:33:03.791+0000] {subprocess.py:86} INFO - Output:
[2023-08-12T15:33:03.793+0000] {subprocess.py:93} INFO - bash: cannot set terminal process group (-1): Inappropriate ioctl for device
[2023-08-12T15:33:03.793+0000] {subprocess.py:93} INFO - bash: no job control in this shell
[2023-08-12T15:33:04.138+0000] {subprocess.py:93} INFO - Debug directory: /home/***
[2023-08-12T15:33:04.138+0000] {subprocess.py:93} INFO - Current working dir: /home/***
[2023-08-12T15:33:04.404+0000] {subprocess.py:93} INFO - WARNING: A conda environment already exists at '/home/***/conda/envs/training_env'
[2023-08-12T15:33:04.404+0000] {subprocess.py:93} INFO - Remove existing environment (y/[n])?
[2023-08-12T15:33:04.404+0000] {subprocess.py:93} INFO - 
[2023-08-12T15:33:04.404+0000] {subprocess.py:93} INFO - CondaSystemExit: Exiting.
[2023-08-12T15:33:04.405+0000] {subprocess.py:93} INFO - 
[2023-08-12T15:33:05.142+0000] {subprocess.py:93} INFO - # conda environments:
[2023-08-12T15:33:05.142+0000] {subprocess.py:93} INFO - #
[2023-08-12T15:33:05.142+0000] {subprocess.py:93} INFO - base                     /home/***/conda
[2023-08-12T15:33:05.142+0000] {subprocess.py:93} INFO - training_env          *  /home/***/conda/envs/training_env
[2023-08-12T15:33:05.142+0000] {subprocess.py:93} INFO - 
[2023-08-12T15:33:07.187+0000] {subprocess.py:93} INFO - Collecting package metadata (current_repodata.json): ...working... done
[2023-08-12T15:33:07.264+0000] {subprocess.py:93} INFO - Solving environment: ...working... done
[2023-08-12T15:33:07.279+0000] {subprocess.py:93} INFO - 
[2023-08-12T15:33:07.279+0000] {subprocess.py:93} INFO - 
[2023-08-12T15:33:07.279+0000] {subprocess.py:93} INFO - ==> WARNING: A newer version of conda exists. <==
[2023-08-12T15:33:07.279+0000] {subprocess.py:93} INFO -   current version: 23.3.1
[2023-08-12T15:33:07.279+0000] {subprocess.py:93} INFO -   latest version: 23.7.2
[2023-08-12T15:33:07.279+0000] {subprocess.py:93} INFO - 
[2023-08-12T15:33:07.280+0000] {subprocess.py:93} INFO - Please update conda by running
[2023-08-12T15:33:07.280+0000] {subprocess.py:93} INFO - 
[2023-08-12T15:33:07.280+0000] {subprocess.py:93} INFO -     $ conda update -n base -c defaults conda
[2023-08-12T15:33:07.280+0000] {subprocess.py:93} INFO - 
[2023-08-12T15:33:07.280+0000] {subprocess.py:93} INFO - Or to minimize the number of packages updated during conda update use
[2023-08-12T15:33:07.280+0000] {subprocess.py:93} INFO - 
[2023-08-12T15:33:07.280+0000] {subprocess.py:93} INFO -      conda install conda=23.7.2
[2023-08-12T15:33:07.280+0000] {subprocess.py:93} INFO - 
[2023-08-12T15:33:07.280+0000] {subprocess.py:93} INFO - 
[2023-08-12T15:33:07.280+0000] {subprocess.py:93} INFO - 
[2023-08-12T15:33:07.280+0000] {subprocess.py:93} INFO - # All requested packages already installed.
[2023-08-12T15:33:07.280+0000] {subprocess.py:93} INFO - 
[2023-08-12T15:33:07.744+0000] {subprocess.py:93} INFO - Looking in links: https://download.pytorch.org/whl/torch_stable.html
[2023-08-12T15:33:07.744+0000] {subprocess.py:93} INFO - Requirement already satisfied: pandas in ./conda/envs/training_env/lib/python3.11/site-packages (from -r /home/***/dog_cat_mlops/ml/requirements.txt (line 1)) (2.0.3)
[2023-08-12T15:33:07.745+0000] {subprocess.py:93} INFO - Requirement already satisfied: numpy in ./conda/envs/training_env/lib/python3.11/site-packages (from -r /home/***/dog_cat_mlops/ml/requirements.txt (line 2)) (1.25.2)
[2023-08-12T15:33:07.746+0000] {subprocess.py:93} INFO - Requirement already satisfied: torch==2.0.1+cpu in ./conda/envs/training_env/lib/python3.11/site-packages (from -r /home/***/dog_cat_mlops/ml/requirements.txt (line 5)) (2.0.1+cpu)
[2023-08-12T15:33:07.747+0000] {subprocess.py:93} INFO - Requirement already satisfied: torchvision==0.15.2+cpu in ./conda/envs/training_env/lib/python3.11/site-packages (from -r /home/***/dog_cat_mlops/ml/requirements.txt (line 6)) (0.15.2+cpu)
[2023-08-12T15:33:07.748+0000] {subprocess.py:93} INFO - Requirement already satisfied: torchmetrics==0.11.4 in ./conda/envs/training_env/lib/python3.11/site-packages (from -r /home/***/dog_cat_mlops/ml/requirements.txt (line 7)) (0.11.4)
[2023-08-12T15:33:07.750+0000] {subprocess.py:93} INFO - Requirement already satisfied: filelock in ./conda/envs/training_env/lib/python3.11/site-packages (from torch==2.0.1+cpu->-r /home/***/dog_cat_mlops/ml/requirements.txt (line 5)) (3.12.2)
[2023-08-12T15:33:07.751+0000] {subprocess.py:93} INFO - Requirement already satisfied: typing-extensions in ./conda/envs/training_env/lib/python3.11/site-packages (from torch==2.0.1+cpu->-r /home/***/dog_cat_mlops/ml/requirements.txt (line 5)) (4.7.1)
[2023-08-12T15:33:07.751+0000] {subprocess.py:93} INFO - Requirement already satisfied: sympy in ./conda/envs/training_env/lib/python3.11/site-packages (from torch==2.0.1+cpu->-r /home/***/dog_cat_mlops/ml/requirements.txt (line 5)) (1.12)
[2023-08-12T15:33:07.752+0000] {subprocess.py:93} INFO - Requirement already satisfied: networkx in ./conda/envs/training_env/lib/python3.11/site-packages (from torch==2.0.1+cpu->-r /home/***/dog_cat_mlops/ml/requirements.txt (line 5)) (3.1)
[2023-08-12T15:33:07.752+0000] {subprocess.py:93} INFO - Requirement already satisfied: jinja2 in ./conda/envs/training_env/lib/python3.11/site-packages (from torch==2.0.1+cpu->-r /home/***/dog_cat_mlops/ml/requirements.txt (line 5)) (3.1.2)
[2023-08-12T15:33:07.755+0000] {subprocess.py:93} INFO - Requirement already satisfied: requests in ./conda/envs/training_env/lib/python3.11/site-packages (from torchvision==0.15.2+cpu->-r /home/***/dog_cat_mlops/ml/requirements.txt (line 6)) (2.31.0)
[2023-08-12T15:33:07.756+0000] {subprocess.py:93} INFO - Requirement already satisfied: pillow!=8.3.*,>=5.3.0 in ./conda/envs/training_env/lib/python3.11/site-packages (from torchvision==0.15.2+cpu->-r /home/***/dog_cat_mlops/ml/requirements.txt (line 6)) (10.0.0)
[2023-08-12T15:33:07.782+0000] {subprocess.py:93} INFO - Requirement already satisfied: packaging in ./conda/envs/training_env/lib/python3.11/site-packages (from torchmetrics==0.11.4->-r /home/***/dog_cat_mlops/ml/requirements.txt (line 7)) (23.1)
[2023-08-12T15:33:07.816+0000] {subprocess.py:93} INFO - Requirement already satisfied: python-dateutil>=2.8.2 in ./conda/envs/training_env/lib/python3.11/site-packages (from pandas->-r /home/***/dog_cat_mlops/ml/requirements.txt (line 1)) (2.8.2)
[2023-08-12T15:33:07.817+0000] {subprocess.py:93} INFO - Requirement already satisfied: pytz>=2020.1 in ./conda/envs/training_env/lib/python3.11/site-packages (from pandas->-r /home/***/dog_cat_mlops/ml/requirements.txt (line 1)) (2023.3)
[2023-08-12T15:33:07.818+0000] {subprocess.py:93} INFO - Requirement already satisfied: tzdata>=2022.1 in ./conda/envs/training_env/lib/python3.11/site-packages (from pandas->-r /home/***/dog_cat_mlops/ml/requirements.txt (line 1)) (2023.3)
[2023-08-12T15:33:07.827+0000] {subprocess.py:93} INFO - Requirement already satisfied: six>=1.5 in ./conda/envs/training_env/lib/python3.11/site-packages (from python-dateutil>=2.8.2->pandas->-r /home/***/dog_cat_mlops/ml/requirements.txt (line 1)) (1.16.0)
[2023-08-12T15:33:07.836+0000] {subprocess.py:93} INFO - Requirement already satisfied: MarkupSafe>=2.0 in ./conda/envs/training_env/lib/python3.11/site-packages (from jinja2->torch==2.0.1+cpu->-r /home/***/dog_cat_mlops/ml/requirements.txt (line 5)) (2.1.3)
[2023-08-12T15:33:07.850+0000] {subprocess.py:93} INFO - Requirement already satisfied: charset-normalizer<4,>=2 in ./conda/envs/training_env/lib/python3.11/site-packages (from requests->torchvision==0.15.2+cpu->-r /home/***/dog_cat_mlops/ml/requirements.txt (line 6)) (3.2.0)
[2023-08-12T15:33:07.851+0000] {subprocess.py:93} INFO - Requirement already satisfied: idna<4,>=2.5 in ./conda/envs/training_env/lib/python3.11/site-packages (from requests->torchvision==0.15.2+cpu->-r /home/***/dog_cat_mlops/ml/requirements.txt (line 6)) (3.4)
[2023-08-12T15:33:07.851+0000] {subprocess.py:93} INFO - Requirement already satisfied: urllib3<3,>=1.21.1 in ./conda/envs/training_env/lib/python3.11/site-packages (from requests->torchvision==0.15.2+cpu->-r /home/***/dog_cat_mlops/ml/requirements.txt (line 6)) (2.0.4)
[2023-08-12T15:33:07.852+0000] {subprocess.py:93} INFO - Requirement already satisfied: certifi>=2017.4.17 in ./conda/envs/training_env/lib/python3.11/site-packages (from requests->torchvision==0.15.2+cpu->-r /home/***/dog_cat_mlops/ml/requirements.txt (line 6)) (2023.7.22)
[2023-08-12T15:33:07.854+0000] {subprocess.py:93} INFO - Requirement already satisfied: mpmath>=0.19 in ./conda/envs/training_env/lib/python3.11/site-packages (from sympy->torch==2.0.1+cpu->-r /home/***/dog_cat_mlops/ml/requirements.txt (line 5)) (1.3.0)
[2023-08-12T15:33:08.210+0000] {subprocess.py:93} INFO - Current working dir: /home/***
[2023-08-12T15:33:08.383+0000] {subprocess.py:93} INFO - Need to download db first
[2023-08-12T15:33:08.384+0000] {subprocess.py:93} INFO - groupadd: Permission denied.
[2023-08-12T15:33:08.384+0000] {subprocess.py:93} INFO - groupadd: cannot lock /etc/group; try again later.
[2023-08-12T15:33:08.384+0000] {subprocess.py:97} INFO - Command exited with return code 10
[2023-08-12T15:33:08.390+0000] {taskinstance.py:1824} ERROR - Task failed with exception
Traceback (most recent call last):
  File "/home/airflow/.local/lib/python3.10/site-packages/airflow/operators/bash.py", line 210, in execute
    raise AirflowException(
airflow.exceptions.AirflowException: Bash command failed. The command returned a non-zero exit code 10.
[2023-08-12T15:33:08.391+0000] {taskinstance.py:1345} INFO - Marking task as FAILED. dag_id=tune_dag, task_id=create_env_task, execution_date=20230812T153109, start_date=20230812T153303, end_date=20230812T153308
[2023-08-12T15:33:08.399+0000] {warnings.py:109} WARNING - /home/***/.local/lib/python3.10/site-packages/***/utils/email.py:152: RemovedInAirflow3Warning: Fetching SMTP credentials from configuration variables will be deprecated in a future release. Please set credentials using a connection instead.
  send_mime_email(e_from=mail_from, e_to=recipients, mime_msg=msg, conn_id=conn_id, dryrun=dryrun)

[2023-08-12T15:33:08.400+0000] {configuration.py:676} WARNING - section/key [smtp/smtp_user] not found in config
[2023-08-12T15:33:08.400+0000] {email.py:268} INFO - Email alerting: attempt 1
[2023-08-12T15:33:08.402+0000] {configuration.py:676} WARNING - section/key [smtp/smtp_user] not found in config
[2023-08-12T15:33:08.402+0000] {email.py:268} INFO - Email alerting: attempt 1
[2023-08-12T15:33:08.403+0000] {taskinstance.py:1889} ERROR - Failed to send email to: thanhdong18891@gmail.com
Traceback (most recent call last):
  File "/home/airflow/.local/lib/python3.10/site-packages/airflow/models/taskinstance.py", line 1407, in _run_raw_task
    self._execute_task_with_callbacks(context, test_mode)
  File "/home/airflow/.local/lib/python3.10/site-packages/airflow/models/taskinstance.py", line 1558, in _execute_task_with_callbacks
    result = self._execute_task(context, task_orig)
  File "/home/airflow/.local/lib/python3.10/site-packages/airflow/models/taskinstance.py", line 1628, in _execute_task
    result = execute_callable(context=context)
  File "/home/airflow/.local/lib/python3.10/site-packages/airflow/operators/bash.py", line 210, in execute
    raise AirflowException(
airflow.exceptions.AirflowException: Bash command failed. The command returned a non-zero exit code 10.

During handling of the above exception, another exception occurred:

Traceback (most recent call last):
  File "/home/airflow/.local/lib/python3.10/site-packages/airflow/models/taskinstance.py", line 2295, in email_alert
    send_email(task.email, subject, html_content)
  File "/home/airflow/.local/lib/python3.10/site-packages/airflow/utils/email.py", line 78, in send_email
    return backend(
  File "/home/airflow/.local/lib/python3.10/site-packages/airflow/utils/email.py", line 152, in send_email_smtp
    send_mime_email(e_from=mail_from, e_to=recipients, mime_msg=msg, conn_id=conn_id, dryrun=dryrun)
  File "/home/airflow/.local/lib/python3.10/site-packages/airflow/utils/email.py", line 270, in send_mime_email
    smtp_conn = _get_smtp_connection(smtp_host, smtp_port, smtp_timeout, smtp_ssl)
  File "/home/airflow/.local/lib/python3.10/site-packages/airflow/utils/email.py", line 317, in _get_smtp_connection
    else smtplib.SMTP(host=host, port=port, timeout=timeout)
  File "/usr/local/lib/python3.10/smtplib.py", line 255, in __init__
    (code, msg) = self.connect(host, port)
  File "/usr/local/lib/python3.10/smtplib.py", line 341, in connect
    self.sock = self._get_socket(host, port, self.timeout)
  File "/usr/local/lib/python3.10/smtplib.py", line 312, in _get_socket
    return socket.create_connection((host, port), timeout,
  File "/usr/local/lib/python3.10/socket.py", line 845, in create_connection
    raise err
  File "/usr/local/lib/python3.10/socket.py", line 833, in create_connection
    sock.connect(sa)
OSError: [Errno 99] Cannot assign requested address

During handling of the above exception, another exception occurred:

Traceback (most recent call last):
  File "/home/airflow/.local/lib/python3.10/site-packages/airflow/models/taskinstance.py", line 1887, in handle_failure
    self.email_alert(error, task)
  File "/home/airflow/.local/lib/python3.10/site-packages/airflow/models/taskinstance.py", line 2297, in email_alert
    send_email(task.email, subject, html_content_err)
  File "/home/airflow/.local/lib/python3.10/site-packages/airflow/utils/email.py", line 78, in send_email
    return backend(
  File "/home/airflow/.local/lib/python3.10/site-packages/airflow/utils/email.py", line 152, in send_email_smtp
    send_mime_email(e_from=mail_from, e_to=recipients, mime_msg=msg, conn_id=conn_id, dryrun=dryrun)
  File "/home/airflow/.local/lib/python3.10/site-packages/airflow/utils/email.py", line 270, in send_mime_email
    smtp_conn = _get_smtp_connection(smtp_host, smtp_port, smtp_timeout, smtp_ssl)
  File "/home/airflow/.local/lib/python3.10/site-packages/airflow/utils/email.py", line 317, in _get_smtp_connection
    else smtplib.SMTP(host=host, port=port, timeout=timeout)
  File "/usr/local/lib/python3.10/smtplib.py", line 255, in __init__
    (code, msg) = self.connect(host, port)
  File "/usr/local/lib/python3.10/smtplib.py", line 341, in connect
    self.sock = self._get_socket(host, port, self.timeout)
  File "/usr/local/lib/python3.10/smtplib.py", line 312, in _get_socket
    return socket.create_connection((host, port), timeout,
  File "/usr/local/lib/python3.10/socket.py", line 845, in create_connection
    raise err
  File "/usr/local/lib/python3.10/socket.py", line 833, in create_connection
    sock.connect(sa)
OSError: [Errno 99] Cannot assign requested address
[2023-08-12T15:33:08.408+0000] {standard_task_runner.py:104} ERROR - Failed to execute job 108 for task create_env_task (Bash command failed. The command returned a non-zero exit code 10.; 242)
[2023-08-12T15:33:08.442+0000] {local_task_job_runner.py:225} INFO - Task exited with return code 1
[2023-08-12T15:33:08.482+0000] {taskinstance.py:2651} INFO - 0 downstream tasks scheduled from follow-on schedule check
