[2023-08-13T14:56:27.802+0000] {taskinstance.py:1103} INFO - Dependencies all met for dep_context=non-requeueable deps ti=<TaskInstance: tune_dag.tune_task manual__2023-08-13T14:56:19.200243+00:00 [queued]>
[2023-08-13T14:56:27.806+0000] {taskinstance.py:1103} INFO - Dependencies all met for dep_context=requeueable deps ti=<TaskInstance: tune_dag.tune_task manual__2023-08-13T14:56:19.200243+00:00 [queued]>
[2023-08-13T14:56:27.806+0000] {taskinstance.py:1308} INFO - Starting attempt 2 of 2
[2023-08-13T14:56:27.811+0000] {taskinstance.py:1327} INFO - Executing <Task(BashOperator): tune_task> on 2023-08-13 14:56:19.200243+00:00
[2023-08-13T14:56:27.815+0000] {standard_task_runner.py:57} INFO - Started process 216 to run task
[2023-08-13T14:56:27.817+0000] {standard_task_runner.py:84} INFO - Running: ['***', 'tasks', 'run', 'tune_dag', 'tune_task', 'manual__2023-08-13T14:56:19.200243+00:00', '--job-id', '174', '--raw', '--subdir', 'DAGS_FOLDER/scripts/tune_ml.py', '--cfg-path', '/tmp/tmpm_0kbvkl']
[2023-08-13T14:56:27.818+0000] {standard_task_runner.py:85} INFO - Job 174: Subtask tune_task
[2023-08-13T14:56:27.835+0000] {task_command.py:410} INFO - Running <TaskInstance: tune_dag.tune_task manual__2023-08-13T14:56:19.200243+00:00 [running]> on host a6a40f1038a0
[2023-08-13T14:56:27.865+0000] {taskinstance.py:1545} INFO - Exporting env vars: AIRFLOW_CTX_DAG_EMAIL='thanhdong18891@gmail.com' AIRFLOW_CTX_DAG_OWNER='DongNT17' AIRFLOW_CTX_DAG_ID='tune_dag' AIRFLOW_CTX_TASK_ID='tune_task' AIRFLOW_CTX_EXECUTION_DATE='2023-08-13T14:56:19.200243+00:00' AIRFLOW_CTX_TRY_NUMBER='2' AIRFLOW_CTX_DAG_RUN_ID='manual__2023-08-13T14:56:19.200243+00:00'
[2023-08-13T14:56:27.866+0000] {subprocess.py:63} INFO - Tmp dir root location: 
 /tmp
[2023-08-13T14:56:27.866+0000] {subprocess.py:75} INFO - Running command: ['/bin/bash', '-c', ' bash -i /opt/***/dags/scripts/train.sh ']
[2023-08-13T14:56:27.873+0000] {subprocess.py:86} INFO - Output:
[2023-08-13T14:56:27.875+0000] {subprocess.py:93} INFO - bash: cannot set terminal process group (-1): Inappropriate ioctl for device
[2023-08-13T14:56:27.875+0000] {subprocess.py:93} INFO - bash: no job control in this shell
[2023-08-13T14:56:28.922+0000] {subprocess.py:93} INFO - # conda environments:
[2023-08-13T14:56:28.922+0000] {subprocess.py:93} INFO - #
[2023-08-13T14:56:28.922+0000] {subprocess.py:93} INFO - base                     /home/***/conda
[2023-08-13T14:56:28.922+0000] {subprocess.py:93} INFO - training_env          *  /home/***/conda/envs/training_env
[2023-08-13T14:56:28.922+0000] {subprocess.py:93} INFO - 
[2023-08-13T14:56:28.982+0000] {subprocess.py:93} INFO - Traceback (most recent call last):
[2023-08-13T14:56:28.982+0000] {subprocess.py:93} INFO -   File "/home/***/dog_cat_mlops/./ml/train.py", line 1, in <module>
[2023-08-13T14:56:28.982+0000] {subprocess.py:93} INFO -     from preprocessing import *
[2023-08-13T14:56:28.982+0000] {subprocess.py:93} INFO -   File "/home/***/dog_cat_mlops/ml/preprocessing.py", line 1, in <module>
[2023-08-13T14:56:28.982+0000] {subprocess.py:93} INFO -     import torchvision.datasets as dset
[2023-08-13T14:56:28.982+0000] {subprocess.py:93} INFO - ModuleNotFoundError: No module named 'torchvision'
[2023-08-13T14:56:28.983+0000] {subprocess.py:97} INFO - Command exited with return code 1
[2023-08-13T14:56:28.988+0000] {taskinstance.py:1824} ERROR - Task failed with exception
Traceback (most recent call last):
  File "/home/airflow/.local/lib/python3.10/site-packages/airflow/operators/bash.py", line 210, in execute
    raise AirflowException(
airflow.exceptions.AirflowException: Bash command failed. The command returned a non-zero exit code 1.
[2023-08-13T14:56:28.990+0000] {taskinstance.py:1345} INFO - Marking task as FAILED. dag_id=tune_dag, task_id=tune_task, execution_date=20230813T145619, start_date=20230813T145627, end_date=20230813T145628
[2023-08-13T14:56:28.997+0000] {warnings.py:109} WARNING - /home/***/.local/lib/python3.10/site-packages/***/utils/email.py:152: RemovedInAirflow3Warning: Fetching SMTP credentials from configuration variables will be deprecated in a future release. Please set credentials using a connection instead.
  send_mime_email(e_from=mail_from, e_to=recipients, mime_msg=msg, conn_id=conn_id, dryrun=dryrun)

[2023-08-13T14:56:28.997+0000] {configuration.py:676} WARNING - section/key [smtp/smtp_user] not found in config
[2023-08-13T14:56:28.997+0000] {email.py:268} INFO - Email alerting: attempt 1
[2023-08-13T14:56:29.000+0000] {configuration.py:676} WARNING - section/key [smtp/smtp_user] not found in config
[2023-08-13T14:56:29.000+0000] {email.py:268} INFO - Email alerting: attempt 1
[2023-08-13T14:56:29.000+0000] {taskinstance.py:1889} ERROR - Failed to send email to: thanhdong18891@gmail.com
Traceback (most recent call last):
  File "/home/airflow/.local/lib/python3.10/site-packages/airflow/models/taskinstance.py", line 1407, in _run_raw_task
    self._execute_task_with_callbacks(context, test_mode)
  File "/home/airflow/.local/lib/python3.10/site-packages/airflow/models/taskinstance.py", line 1558, in _execute_task_with_callbacks
    result = self._execute_task(context, task_orig)
  File "/home/airflow/.local/lib/python3.10/site-packages/airflow/models/taskinstance.py", line 1628, in _execute_task
    result = execute_callable(context=context)
  File "/home/airflow/.local/lib/python3.10/site-packages/airflow/operators/bash.py", line 210, in execute
    raise AirflowException(
airflow.exceptions.AirflowException: Bash command failed. The command returned a non-zero exit code 1.

During handling of the above exception, another exception occurred:

Traceback (most recent call last):
  File "/home/airflow/.local/lib/python3.10/site-packages/airflow/models/taskinstance.py", line 2295, in email_alert
    send_email(task.email, subject, html_content)
  File "/home/airflow/.local/lib/python3.10/site-packages/airflow/utils/email.py", line 78, in send_email
    return backend(
  File "/home/airflow/.local/lib/python3.10/site-packages/airflow/utils/email.py", line 152, in send_email_smtp
    send_mime_email(e_from=mail_from, e_to=recipients, mime_msg=msg, conn_id=conn_id, dryrun=dryrun)
  File "/home/airflow/.local/lib/python3.10/site-packages/airflow/utils/email.py", line 270, in send_mime_email
    smtp_conn = _get_smtp_connection(smtp_host, smtp_port, smtp_timeout, smtp_ssl)
  File "/home/airflow/.local/lib/python3.10/site-packages/airflow/utils/email.py", line 317, in _get_smtp_connection
    else smtplib.SMTP(host=host, port=port, timeout=timeout)
  File "/usr/local/lib/python3.10/smtplib.py", line 255, in __init__
    (code, msg) = self.connect(host, port)
  File "/usr/local/lib/python3.10/smtplib.py", line 341, in connect
    self.sock = self._get_socket(host, port, self.timeout)
  File "/usr/local/lib/python3.10/smtplib.py", line 312, in _get_socket
    return socket.create_connection((host, port), timeout,
  File "/usr/local/lib/python3.10/socket.py", line 845, in create_connection
    raise err
  File "/usr/local/lib/python3.10/socket.py", line 833, in create_connection
    sock.connect(sa)
OSError: [Errno 99] Cannot assign requested address

During handling of the above exception, another exception occurred:

Traceback (most recent call last):
  File "/home/airflow/.local/lib/python3.10/site-packages/airflow/models/taskinstance.py", line 1887, in handle_failure
    self.email_alert(error, task)
  File "/home/airflow/.local/lib/python3.10/site-packages/airflow/models/taskinstance.py", line 2297, in email_alert
    send_email(task.email, subject, html_content_err)
  File "/home/airflow/.local/lib/python3.10/site-packages/airflow/utils/email.py", line 78, in send_email
    return backend(
  File "/home/airflow/.local/lib/python3.10/site-packages/airflow/utils/email.py", line 152, in send_email_smtp
    send_mime_email(e_from=mail_from, e_to=recipients, mime_msg=msg, conn_id=conn_id, dryrun=dryrun)
  File "/home/airflow/.local/lib/python3.10/site-packages/airflow/utils/email.py", line 270, in send_mime_email
    smtp_conn = _get_smtp_connection(smtp_host, smtp_port, smtp_timeout, smtp_ssl)
  File "/home/airflow/.local/lib/python3.10/site-packages/airflow/utils/email.py", line 317, in _get_smtp_connection
    else smtplib.SMTP(host=host, port=port, timeout=timeout)
  File "/usr/local/lib/python3.10/smtplib.py", line 255, in __init__
    (code, msg) = self.connect(host, port)
  File "/usr/local/lib/python3.10/smtplib.py", line 341, in connect
    self.sock = self._get_socket(host, port, self.timeout)
  File "/usr/local/lib/python3.10/smtplib.py", line 312, in _get_socket
    return socket.create_connection((host, port), timeout,
  File "/usr/local/lib/python3.10/socket.py", line 845, in create_connection
    raise err
  File "/usr/local/lib/python3.10/socket.py", line 833, in create_connection
    sock.connect(sa)
OSError: [Errno 99] Cannot assign requested address
[2023-08-13T14:56:29.008+0000] {standard_task_runner.py:104} ERROR - Failed to execute job 174 for task tune_task (Bash command failed. The command returned a non-zero exit code 1.; 216)
[2023-08-13T14:56:29.030+0000] {local_task_job_runner.py:225} INFO - Task exited with return code 1
[2023-08-13T14:56:29.037+0000] {taskinstance.py:2651} INFO - 0 downstream tasks scheduled from follow-on schedule check
