[2023-08-13T14:58:04.766+0000] {taskinstance.py:1103} INFO - Dependencies all met for dep_context=non-requeueable deps ti=<TaskInstance: tune_dag.check_gpu manual__2023-08-13T14:56:19.200243+00:00 [queued]>
[2023-08-13T14:58:04.770+0000] {taskinstance.py:1103} INFO - Dependencies all met for dep_context=requeueable deps ti=<TaskInstance: tune_dag.check_gpu manual__2023-08-13T14:56:19.200243+00:00 [queued]>
[2023-08-13T14:58:04.770+0000] {taskinstance.py:1308} INFO - Starting attempt 1 of 2
[2023-08-13T14:58:04.776+0000] {taskinstance.py:1327} INFO - Executing <Task(_PythonDecoratedOperator): check_gpu> on 2023-08-13 14:56:19.200243+00:00
[2023-08-13T14:58:04.780+0000] {standard_task_runner.py:57} INFO - Started process 290 to run task
[2023-08-13T14:58:04.781+0000] {standard_task_runner.py:84} INFO - Running: ['***', 'tasks', 'run', 'tune_dag', 'check_gpu', 'manual__2023-08-13T14:56:19.200243+00:00', '--job-id', '175', '--raw', '--subdir', 'DAGS_FOLDER/scripts/tune_ml.py', '--cfg-path', '/tmp/tmp2ixl_qg9']
[2023-08-13T14:58:04.782+0000] {standard_task_runner.py:85} INFO - Job 175: Subtask check_gpu
[2023-08-13T14:58:04.799+0000] {task_command.py:410} INFO - Running <TaskInstance: tune_dag.check_gpu manual__2023-08-13T14:56:19.200243+00:00 [running]> on host a6a40f1038a0
[2023-08-13T14:58:04.828+0000] {taskinstance.py:1545} INFO - Exporting env vars: AIRFLOW_CTX_DAG_EMAIL='thanhdong18891@gmail.com' AIRFLOW_CTX_DAG_OWNER='DongNT17' AIRFLOW_CTX_DAG_ID='tune_dag' AIRFLOW_CTX_TASK_ID='check_gpu' AIRFLOW_CTX_EXECUTION_DATE='2023-08-13T14:56:19.200243+00:00' AIRFLOW_CTX_TRY_NUMBER='1' AIRFLOW_CTX_DAG_RUN_ID='manual__2023-08-13T14:56:19.200243+00:00'
[2023-08-13T15:07:24.751+0000] {taskinstance.py:1824} ERROR - Task failed with exception
Traceback (most recent call last):
  File "/home/airflow/.local/lib/python3.10/site-packages/airflow/decorators/base.py", line 220, in execute
    return_value = super().execute(context)
  File "/home/airflow/.local/lib/python3.10/site-packages/airflow/operators/python.py", line 181, in execute
    return_value = self.execute_callable()
  File "/home/airflow/.local/lib/python3.10/site-packages/airflow/operators/python.py", line 198, in execute_callable
    return self.python_callable(*self.op_args, **self.op_kwargs)
  File "/opt/airflow/dags/scripts/tune_ml.py", line 61, in start_gpu_container
    response = client.containers.run(
  File "/home/airflow/.local/lib/python3.10/site-packages/docker/models/containers.py", line 887, in run
    raise ContainerError(
docker.errors.ContainerError: Command 'python3 ../ml/train.py' in image 'pytorch/pytorch' returned non-zero exit status 2: b"python3: can't open file '/workspace/../ml/train.py': [Errno 2] No such file or directory\n"
[2023-08-13T15:07:24.755+0000] {taskinstance.py:1345} INFO - Marking task as UP_FOR_RETRY. dag_id=tune_dag, task_id=check_gpu, execution_date=20230813T145619, start_date=20230813T145804, end_date=20230813T150724
[2023-08-13T15:07:24.761+0000] {standard_task_runner.py:104} ERROR - Failed to execute job 175 for task check_gpu (Command 'python3 ../ml/train.py' in image 'pytorch/pytorch' returned non-zero exit status 2: b"python3: can't open file '/workspace/../ml/train.py': [Errno 2] No such file or directory\n"; 290)
[2023-08-13T15:07:24.799+0000] {local_task_job_runner.py:225} INFO - Task exited with return code 1
[2023-08-13T15:07:24.824+0000] {taskinstance.py:2651} INFO - 0 downstream tasks scheduled from follow-on schedule check
