[2023-08-12T04:55:47.493+0000] {taskinstance.py:1103} INFO - Dependencies all met for dep_context=non-requeueable deps ti=<TaskInstance: tune_dag.tune_task manual__2023-08-12T04:53:48.778402+00:00 [queued]>
[2023-08-12T04:55:47.497+0000] {taskinstance.py:1103} INFO - Dependencies all met for dep_context=requeueable deps ti=<TaskInstance: tune_dag.tune_task manual__2023-08-12T04:53:48.778402+00:00 [queued]>
[2023-08-12T04:55:47.497+0000] {taskinstance.py:1308} INFO - Starting attempt 1 of 2
[2023-08-12T04:55:47.502+0000] {taskinstance.py:1327} INFO - Executing <Task(BashOperator): tune_task> on 2023-08-12 04:53:48.778402+00:00
[2023-08-12T04:55:47.506+0000] {standard_task_runner.py:57} INFO - Started process 242 to run task
[2023-08-12T04:55:47.508+0000] {standard_task_runner.py:84} INFO - Running: ['***', 'tasks', 'run', 'tune_dag', 'tune_task', 'manual__2023-08-12T04:53:48.778402+00:00', '--job-id', '81', '--raw', '--subdir', 'DAGS_FOLDER/scripts/tune_ml.py', '--cfg-path', '/tmp/tmp3qnz2bhr']
[2023-08-12T04:55:47.509+0000] {standard_task_runner.py:85} INFO - Job 81: Subtask tune_task
[2023-08-12T04:55:47.527+0000] {task_command.py:410} INFO - Running <TaskInstance: tune_dag.tune_task manual__2023-08-12T04:53:48.778402+00:00 [running]> on host 7e4faac5ec6d
[2023-08-12T04:55:47.557+0000] {taskinstance.py:1545} INFO - Exporting env vars: AIRFLOW_CTX_DAG_EMAIL='thanhdong18891@gmail.com' AIRFLOW_CTX_DAG_OWNER='DongNT17' AIRFLOW_CTX_DAG_ID='tune_dag' AIRFLOW_CTX_TASK_ID='tune_task' AIRFLOW_CTX_EXECUTION_DATE='2023-08-12T04:53:48.778402+00:00' AIRFLOW_CTX_TRY_NUMBER='1' AIRFLOW_CTX_DAG_RUN_ID='manual__2023-08-12T04:53:48.778402+00:00'
[2023-08-12T04:55:47.558+0000] {subprocess.py:63} INFO - Tmp dir root location: 
 /tmp
[2023-08-12T04:55:47.558+0000] {subprocess.py:75} INFO - Running command: ['/bin/bash', '-c', ' bash -i /opt/***/dags/scripts/train.sh ']
[2023-08-12T04:55:47.566+0000] {subprocess.py:86} INFO - Output:
[2023-08-12T04:55:47.568+0000] {subprocess.py:93} INFO - bash: cannot set terminal process group (-1): Inappropriate ioctl for device
[2023-08-12T04:55:47.568+0000] {subprocess.py:93} INFO - bash: no job control in this shell
[2023-08-12T04:55:48.598+0000] {subprocess.py:93} INFO - # conda environments:
[2023-08-12T04:55:48.598+0000] {subprocess.py:93} INFO - #
[2023-08-12T04:55:48.598+0000] {subprocess.py:93} INFO - base                     /home/***/conda
[2023-08-12T04:55:48.598+0000] {subprocess.py:93} INFO - training_env          *  /home/***/conda/envs/training_env
[2023-08-12T04:55:48.598+0000] {subprocess.py:93} INFO - 
[2023-08-12T04:55:49.563+0000] {subprocess.py:93} INFO - Traceback (most recent call last):
[2023-08-12T04:55:49.563+0000] {subprocess.py:93} INFO -   File "/home/***/dog_cat_mlops/./ml/train.py", line 17, in <module>
[2023-08-12T04:55:49.563+0000] {subprocess.py:93} INFO -     model = models.resnet50().cuda()
[2023-08-12T04:55:49.563+0000] {subprocess.py:93} INFO -             ^^^^^^^^^^^^^^^^^^^^^^^^
[2023-08-12T04:55:49.563+0000] {subprocess.py:93} INFO -   File "/home/***/conda/envs/training_env/lib/python3.11/site-packages/torch/nn/modules/module.py", line 905, in cuda
[2023-08-12T04:55:49.563+0000] {subprocess.py:93} INFO -     return self._apply(lambda t: t.cuda(device))
[2023-08-12T04:55:49.563+0000] {subprocess.py:93} INFO -            ^^^^^^^^^^^^^^^^^^^^^^^^^^^^^^^^^^^^^
[2023-08-12T04:55:49.563+0000] {subprocess.py:93} INFO -   File "/home/***/conda/envs/training_env/lib/python3.11/site-packages/torch/nn/modules/module.py", line 797, in _apply
[2023-08-12T04:55:49.563+0000] {subprocess.py:93} INFO -     module._apply(fn)
[2023-08-12T04:55:49.563+0000] {subprocess.py:93} INFO -   File "/home/***/conda/envs/training_env/lib/python3.11/site-packages/torch/nn/modules/module.py", line 820, in _apply
[2023-08-12T04:55:49.563+0000] {subprocess.py:93} INFO -     param_applied = fn(param)
[2023-08-12T04:55:49.563+0000] {subprocess.py:93} INFO -                     ^^^^^^^^^
[2023-08-12T04:55:49.563+0000] {subprocess.py:93} INFO -   File "/home/***/conda/envs/training_env/lib/python3.11/site-packages/torch/nn/modules/module.py", line 905, in <lambda>
[2023-08-12T04:55:49.563+0000] {subprocess.py:93} INFO -     return self._apply(lambda t: t.cuda(device))
[2023-08-12T04:55:49.563+0000] {subprocess.py:93} INFO -                                  ^^^^^^^^^^^^^^
[2023-08-12T04:55:49.563+0000] {subprocess.py:93} INFO -   File "/home/***/conda/envs/training_env/lib/python3.11/site-packages/torch/cuda/__init__.py", line 239, in _lazy_init
[2023-08-12T04:55:49.563+0000] {subprocess.py:93} INFO -     raise AssertionError("Torch not compiled with CUDA enabled")
[2023-08-12T04:55:49.564+0000] {subprocess.py:93} INFO - AssertionError: Torch not compiled with CUDA enabled
[2023-08-12T04:55:49.702+0000] {subprocess.py:97} INFO - Command exited with return code 1
[2023-08-12T04:55:49.708+0000] {taskinstance.py:1824} ERROR - Task failed with exception
Traceback (most recent call last):
  File "/home/airflow/.local/lib/python3.10/site-packages/airflow/operators/bash.py", line 210, in execute
    raise AirflowException(
airflow.exceptions.AirflowException: Bash command failed. The command returned a non-zero exit code 1.
[2023-08-12T04:55:49.709+0000] {taskinstance.py:1345} INFO - Marking task as UP_FOR_RETRY. dag_id=tune_dag, task_id=tune_task, execution_date=20230812T045348, start_date=20230812T045547, end_date=20230812T045549
[2023-08-12T04:55:49.723+0000] {standard_task_runner.py:104} ERROR - Failed to execute job 81 for task tune_task (Bash command failed. The command returned a non-zero exit code 1.; 242)
[2023-08-12T04:55:49.764+0000] {local_task_job_runner.py:225} INFO - Task exited with return code 1
[2023-08-12T04:55:49.773+0000] {taskinstance.py:2651} INFO - 0 downstream tasks scheduled from follow-on schedule check
